#VRML_SIM R2022b utf8

EXTERNPROTO "https://raw.githubusercontent.com/cyberbotics/webots/R2022b/projects/objects/backgrounds/protos/TexturedBackground.proto"
EXTERNPROTO "https://raw.githubusercontent.com/cyberbotics/webots/R2022b/projects/objects/backgrounds/protos/TexturedBackgroundLight.proto"
EXTERNPROTO "https://raw.githubusercontent.com/cyberbotics/webots/R2022b/projects/objects/apartment_structure/protos/Wall.proto"
EXTERNPROTO "https://raw.githubusercontent.com/cyberbotics/webots/R2022b/projects/objects/lights/protos/CeilingSpotLight.proto"
EXTERNPROTO "https://raw.githubusercontent.com/cyberbotics/webots/R2022b/projects/objects/floors/protos/Floor.proto"

WorldInfo {
  basicTimeStep 24
}
Viewpoint {
  orientation 0.43475353629795155 -0.2801309186083502 -0.8558715038579492 4.149543824504522
  position 1.8472027448865864 -4.529105945880546 6.67030647196908
}
TexturedBackground {
}
TexturedBackgroundLight {
  luminosity 0
}
DEF wall-e Robot {
  translation 0 0.22 0.0707665
  rotation 0.5827679095566829 -0.5799118369321808 -0.5692836068049717 2.0698844343502762
  children [
    LightSensor {
      translation 4.03236e-13 0.04 0
      rotation 0 0 -1 -1.5708053071795867
      children [
        Shape {
          appearance PBRAppearance {
            baseColor 0 0 0
          }
          geometry Box {
            size 0.01 0.2 0.14
          }
        }
      ]
      name "panel"
      boundingObject Box {
        size 0.01 0.2 0.1
      }
      lookupTable [
        0 0 0
        10 10 0
      ]
    }
    LightSensor {
      translation 0.16 0.02 0.12
      rotation 0 0 1 1.5708
      children [
        Shape {
          appearance PBRAppearance {
            baseColor 0 0 1
          }
          geometry Box {
            size 0.005 0.005 0.005
          }
        }
      ]
      name "light_sensor_r"
      boundingObject Box {
        size 0.005 0.005 0.005
      }
      physics Physics {
      }
      lookupTable [
        0 0 0
        10 10 0
      ]
    }
    LightSensor {
      translation 0.16 0.02 0
      rotation 0 0 1 1.5708
      children [
        Shape {
          appearance PBRAppearance {
            baseColor 0 0 1
          }
          geometry Box {
            size 0.005 0.005 0.005
          }
        }
      ]
      name "light_sensor_c"
      boundingObject Box {
        size 0.005 0.005 0.005
      }
      physics Physics {
      }
      lookupTable [
        0 0 0
        10 10 0
      ]
    }
    LightSensor {
      translation 0.16 0.02 -0.12
      rotation 0 0 1 1.5708
      children [
        Shape {
          appearance PBRAppearance {
            baseColor 0 0 1
          }
          geometry Box {
            size 0.005 0.005 0.005
          }
        }
      ]
      name "light_sensor_l"
      boundingObject Box {
        size 0.005 0.005 0.005
      }
      physics Physics {
      }
      lookupTable [
        0 0 0
        10 10 0
      ]
    }
    DistanceSensor {
      translation 0 0.01 0.05
      rotation 0 1 0 -1.57
      children [
        DEF ddd Shape {
          appearance PBRAppearance {
            baseColor 0.333333 1 0.498039
          }
          geometry Sphere {
            radius 0.01
          }
        }
      ]
      name "distance_sensor_r"
      boundingObject USE ddd
      physics Physics {
      }
      lookupTable [
        0 10 0
        1 0 0
      ]
      type "sonar"
    }
    DistanceSensor {
      translation 0 0.01 -0.05
      rotation 0 1 0 1.57
      children [
        DEF ddd Shape {
          appearance PBRAppearance {
            baseColor 0.333333 1 0.498039
          }
          geometry Sphere {
            radius 0.01
          }
        }
      ]
      name "distance_sensor_l"
      boundingObject USE ddd
      physics Physics {
      }
      lookupTable [
        0 10 0
        1 0 0
      ]
      type "sonar"
    }
    DistanceSensor {
      translation 0.1 0.01 0
      rotation 1 0 0 1.57
      children [
        DEF ddd Shape {
          appearance PBRAppearance {
            baseColor 0.333333 1 0.498039
          }
          geometry Sphere {
            radius 0.01
          }
        }
      ]
      name "distance_sensor"
      boundingObject USE ddd
      physics Physics {
      }
      lookupTable [
        0 10 0
        1 0 0
      ]
      type "sonar"
    }
    BallJoint {
      jointParameters BallJointParameters {
        position -958.3502620561283
        anchor 0.07 -0.04 0
      }
      jointParameters2 JointParameters {
        position -548.5523458507724
      }
      jointParameters3 JointParameters {
        position 4031.7649844006214
      }
      endPoint Solid {
        translation 0.07361959426549902 -0.03999584327616979 0.0014986302679728379
        rotation -0.7173082859203361 -0.4492112145837699 -0.5326144080309917 0.8066414825924015
        children [
          DEF ball Shape {
            appearance PBRAppearance {
              baseColor 1 0 0
            }
            geometry Sphere {
              radius 0.03
            }
          }
        ]
        name "solid(2)"
        boundingObject USE ball
        physics Physics {
        }
      }
    }
    HingeJoint {
      jointParameters HingeJointParameters {
        position 50794.76985743329
        axis 0 0 1
        anchor -0.06 -0.04 -0.05
      }
      device [
        PositionSensor {
          name "l_p_s"
        }
        RotationalMotor {
          name "left_motor"
          acceleration 20
          controlPID 10 4 0
          maxVelocity 100
          minPosition -10
          maxPosition 100000000000
        }
      ]
      endPoint Solid {
        translation -0.06004074114069433 -0.03998674525290019 -0.05000184065243736
        rotation -1.5275474413906216e-06 -4.738539591301535e-06 0.9999999999876064 5.014753324234367
        children [
          DEF wheel Shape {
            appearance PBRAppearance {
              baseColor 1 0 0
            }
            geometry Cylinder {
              height 0.02
              radius 0.03
            }
          }
        ]
        name "solid(1)"
        boundingObject USE wheel
        physics Physics {
        }
      }
    }
    HingeJoint {
      jointParameters HingeJointParameters {
        position 25248.41455912857
        axis 0 0 1
        anchor -0.06 -0.04 0.05
      }
      device [
        PositionSensor {
          name "r_p_s"
        }
        RotationalMotor {
          name "right_motor"
          acceleration 20
          controlPID 10 4 0
          maxVelocity 100
          minPosition -10
          maxPosition 100000000000
        }
      ]
      endPoint Solid {
        translation -0.05999190113846406 -0.040027849139345956 0.05001002093556352
        rotation -9.397307352009822e-07 -1.2390747101826172e-06 0.9999999999987909 3.2465088159414064
        children [
          DEF wheel Shape {
            appearance PBRAppearance {
              baseColor 1 0 0
            }
            geometry Cylinder {
              height 0.02
              radius 0.03
            }
          }
        ]
        boundingObject USE wheel
        physics Physics {
        }
      }
    }
    DEF body Shape {
      appearance PBRAppearance {
      }
      geometry Box {
        size 0.2 0.07 0.14
      }
    }
  ]
  name "wall-e"
  boundingObject USE body
  physics DEF body Physics {
  }
  controller "wall-e-controller"
  supervisor TRUE
}
DEF box01-wall01 Wall {
  translation -0.21 0 0
  name "box01-wall01"
  size 0.01 0.69 0.3
}
DEF box01-wall02 Wall {
  translation 5.19723e-15 0.34 0
  rotation 0 0 1 -1.5707953071795862
  name "box01-wall02"
  size 0.01 0.43 0.3
}
DEF box01-wall03 Wall {
  translation 0.21 0 0
  name "box01-wall03"
  size 0.01 0.69 0.3
}
DEF box02-wall01 Wall {
  translation -0.109997 -0.78 0
  rotation 0 0 1 1.5708
  name "box02-wall01"
  size 0.01 0.36 0.3
}
DEF box02-wall02 Wall {
  translation -0.29 -0.57 0
  name "box02-wall02"
  size 0.01 0.43 0.3
}
DEF box02-wall03 Wall {
  translation 0.39 -0.57 0
  name "box02-wall03"
  size 0.01 0.43 0.3
}
DEF box02-wall04 Wall {
  translation -0.25 -0.35 2.87698e-09
  rotation -9.58979e-09 9.58976e-09 -1 -1.5707953071795862
  name "box02-wall04"
  size 0.01 0.08 0.3
}
DEF box02-wall05 Wall {
  translation 0.3 -0.35 2.87698e-09
  rotation -9.58979e-09 9.58976e-09 -1 -1.5707953071795862
  name "box02-wall05"
  size 0.01 0.18 0.3
}
DEF box03-wall01 Wall {
  translation 0.05 -1.02 0
  name "box03-wall01"
  size 0.01 0.48 0.3
}
DEF box03-wall02 Wall {
  translation 0.39 -1.02 0
  name "box03-wall02"
  size 0.01 0.48 0.3
}
DEF box04-wall01 Wall {
  translation 0.39 -1.62 0
  name "box04-wall01"
  size 0.01 0.72 0.3
}
DEF box04-wall02 Wall {
  translation -0.37 -1.62 0
  name "box04-wall02"
  size 0.01 0.72 0.3
}
DEF box04-wall03 Wall {
  translation 0.0100073 -1.98 0
  rotation 0 0 1 1.5708
  name "box04-wall03"
  size 0.01 0.77 0.3
}
DEF box04-wall04 Wall {
  translation -0.149995 -1.26 0
  rotation 0 0 1 1.5708
  name "box04-wall04"
  size 0.01 0.44 0.3
}
DEF light02 CeilingSpotLight {
  translation 0.18 -0.13 0.33
  name "light02"
  spotLightRadius 0.3
}
DEF light03 CeilingSpotLight {
  translation -0.06 -0.48 0.33
  name "light03"
  spotLightRadius 0.3
}
DEF light04 CeilingSpotLight {
  translation 0.31 -0.7 0.33
  name "light04"
  spotLightRadius 0.3
}
DEF light06 CeilingSpotLight {
  translation -0.21 -1.51 0.33
  rotation 0 1 0 0
  name "light06"
  spotLightRadius 0.3
}
DEF light07 CeilingSpotLight {
  translation -0.05 -1.73 0.33
  rotation 0 1 0 0
  name "light07"
  spotLightRadius 0.3
}
Floor {
}
