#VRML_SIM R2022b utf8

EXTERNPROTO "https://raw.githubusercontent.com/cyberbotics/webots/R2022b/projects/objects/backgrounds/protos/TexturedBackground.proto"
EXTERNPROTO "https://raw.githubusercontent.com/cyberbotics/webots/R2022b/projects/objects/backgrounds/protos/TexturedBackgroundLight.proto"
EXTERNPROTO "https://raw.githubusercontent.com/cyberbotics/webots/R2022b/projects/objects/apartment_structure/protos/Wall.proto"
EXTERNPROTO "https://raw.githubusercontent.com/cyberbotics/webots/R2022b/projects/objects/lights/protos/CeilingSpotLight.proto"
EXTERNPROTO "https://raw.githubusercontent.com/cyberbotics/webots/R2022b/projects/objects/floors/protos/Floor.proto"

WorldInfo {
  basicTimeStep 24
}
Viewpoint {
  orientation 0.48281991918152073 -0.26841685195196313 -0.8335690248742139 4.009493108846986
  position 0.4308809495709074 -0.23422813663947128 1.1054394152792635
}
TexturedBackground {
}
TexturedBackgroundLight {
  luminosity 0
}
DEF wall-e Robot {
  translation 0 0.22 0.0678272
  rotation 0.5863961143034234 -0.5640317958275968 -0.5813843224798398 2.107387580404057
  children [
    LightSensor {
      translation 4.03236e-13 0.04 0
      rotation 0 0 -1 -1.5708053071795867
      children [
        Shape {
          appearance PBRAppearance {
            baseColor 0 0 0
          }
          geometry Box {
            size 0.01 0.2 0.14
          }
        }
      ]
      name "panel"
      boundingObject Box {
        size 0.01 0.2 0.1
      }
      lookupTable [
        0 0 0
        10 10 0
      ]
    }
    LightSensor {
      translation 0.16 0.02 0.12
      rotation 0 0 1 1.5708
      children [
        Shape {
          appearance PBRAppearance {
            baseColor 0 0 1
          }
          geometry Box {
            size 0.005 0.005 0.005
          }
        }
      ]
      name "light_sensor_r"
      boundingObject Box {
        size 0.005 0.005 0.005
      }
      physics Physics {
      }
      lookupTable [
        0 0 0
        10 10 0
      ]
    }
    LightSensor {
      translation 0.16 0.02 0
      rotation 0 0 1 1.5708
      children [
        Shape {
          appearance PBRAppearance {
            baseColor 0 0 1
          }
          geometry Box {
            size 0.005 0.005 0.005
          }
        }
      ]
      name "light_sensor_c"
      boundingObject Box {
        size 0.005 0.005 0.005
      }
      physics Physics {
      }
      lookupTable [
        0 0 0
        10 10 0
      ]
    }
    LightSensor {
      translation 0.16 0.02 -0.12
      rotation 0 0 1 1.5708
      children [
        Shape {
          appearance PBRAppearance {
            baseColor 0 0 1
          }
          geometry Box {
            size 0.005 0.005 0.005
          }
        }
      ]
      name "light_sensor_l"
      boundingObject Box {
        size 0.005 0.005 0.005
      }
      physics Physics {
      }
      lookupTable [
        0 0 0
        10 10 0
      ]
    }
    DistanceSensor {
      translation 0 0.01 0.05
      rotation 0 1 0 -1.57
      children [
        DEF ddd Shape {
          appearance PBRAppearance {
            baseColor 0.333333 1 0.498039
          }
          geometry Sphere {
            radius 0.01
          }
        }
      ]
      name "distance_sensor_r"
      boundingObject USE ddd
      physics Physics {
      }
      lookupTable [
        0 10 0
        1 0 0
      ]
      type "sonar"
    }
    DistanceSensor {
      translation 0 0.01 -0.05
      rotation 0 1 0 1.57
      children [
        DEF ddd Shape {
          appearance PBRAppearance {
            baseColor 0.333333 1 0.498039
          }
          geometry Sphere {
            radius 0.01
          }
        }
      ]
      name "distance_sensor_l"
      boundingObject USE ddd
      physics Physics {
      }
      lookupTable [
        0 10 0
        1 0 0
      ]
      type "sonar"
    }
    DistanceSensor {
      translation 0.1 0.01 0
      rotation 1 0 0 1.57
      children [
        DEF ddd Shape {
          appearance PBRAppearance {
            baseColor 0.333333 1 0.498039
          }
          geometry Sphere {
            radius 0.01
          }
        }
      ]
      name "distance_sensor"
      boundingObject USE ddd
      physics Physics {
      }
      lookupTable [
        0 10 0
        1 0 0
      ]
      type "sonar"
    }
    BallJoint {
      jointParameters BallJointParameters {
        position -921.6887336318985
        anchor 0.07 -0.04 0
      }
      jointParameters2 JointParameters {
        position -546.2164089008866
      }
      jointParameters3 JointParameters {
        position 4039.574367396816
      }
      endPoint Solid {
        translation 0.07095574662239722 -0.04229939432351313 0.0030294738938387304
        rotation -0.814030013827246 0.5655436686528382 -0.1323461198339508 4.287304864280893
        children [
          DEF ball Shape {
            appearance PBRAppearance {
              baseColor 1 0 0
            }
            geometry Sphere {
              radius 0.03
            }
          }
        ]
        name "solid(2)"
        boundingObject USE ball
        physics Physics {
        }
      }
    }
    HingeJoint {
      jointParameters HingeJointParameters {
        position 50821.81231729648
        axis 0 0 1
        anchor -0.06 -0.04 -0.05
      }
      device [
        PositionSensor {
          name "l_p_s"
        }
        RotationalMotor {
          name "left_motor"
          acceleration 20
          controlPID 10 4 0
          maxVelocity 100
          minPosition -10
          maxPosition 100000000000
        }
      ]
      endPoint Solid {
        translation -0.059998955487439255 -0.040042830338070885 -0.05000184065243736
        rotation 5.612393331209671e-06 -7.490837282824921e-06 -0.9999999999561943 5.641898655618018
        children [
          DEF wheel Shape {
            appearance PBRAppearance {
              baseColor 1 0 0
            }
            geometry Cylinder {
              height 0.02
              radius 0.03
            }
          }
        ]
        name "solid(1)"
        boundingObject USE wheel
        physics Physics {
        }
      }
    }
    HingeJoint {
      jointParameters HingeJointParameters {
        position 25275.457051111316
        axis 0 0 1
        anchor -0.06 -0.04 0.05
      }
      device [
        PositionSensor {
          name "r_p_s"
        }
        RotationalMotor {
          name "right_motor"
          acceleration 20
          controlPID 10 4 0
          maxVelocity 100
          minPosition -10
          maxPosition 100000000000
        }
      ]
      endPoint Solid {
        translation -0.059976428278835786 -0.03998310206871107 0.05001002093556352
        rotation 8.759275626784837e-07 -2.7724903380485604e-06 0.9999999999957732 5.1562595699649325
        children [
          DEF wheel Shape {
            appearance PBRAppearance {
              baseColor 1 0 0
            }
            geometry Cylinder {
              height 0.02
              radius 0.03
            }
          }
        ]
        boundingObject USE wheel
        physics Physics {
        }
      }
    }
    DEF body Shape {
      appearance PBRAppearance {
      }
      geometry Box {
        size 0.2 0.07 0.14
      }
    }
  ]
  name "wall-e"
  boundingObject USE body
  physics DEF body Physics {
  }
  controller "wall-e-controller"
  supervisor TRUE
}
DEF box01-wall01 Wall {
  translation -0.21 0 0
  name "box01-wall01"
  size 0.01 0.69 0.3
}
DEF box01-wall02 Wall {
  translation 5.19723e-15 0.34 0
  rotation 0 0 1 -1.5707953071795862
  name "box01-wall02"
  size 0.01 0.43 0.3
}
DEF box01-wall03 Wall {
  translation 0.21 0 0
  name "box01-wall03"
  size 0.01 0.69 0.3
}
DEF box02-wall01 Wall {
  translation -0.109997 -0.78 0
  rotation 0 0 1 1.5708
  name "box02-wall01"
  size 0.01 0.36 0.3
}
DEF box02-wall02 Wall {
  translation -0.29 -0.57 0
  name "box02-wall02"
  size 0.01 0.43 0.3
}
DEF box02-wall03 Wall {
  translation 0.39 -0.57 0
  name "box02-wall03"
  size 0.01 0.43 0.3
}
DEF box02-wall04 Wall {
  translation -0.25 -0.35 2.87698e-09
  rotation -9.58979e-09 9.58976e-09 -1 -1.5707953071795862
  name "box02-wall04"
  size 0.01 0.08 0.3
}
DEF box02-wall05 Wall {
  translation 0.3 -0.35 2.87698e-09
  rotation -9.58979e-09 9.58976e-09 -1 -1.5707953071795862
  name "box02-wall05"
  size 0.01 0.18 0.3
}
DEF box03-wall01 Wall {
  translation 0.07 -1.02 0
  name "box03-wall01"
  size 0.01 0.48 0.3
}
DEF box03-wall02 Wall {
  translation 0.39 -1.02 0
  name "box03-wall02"
  size 0.01 0.48 0.3
}
DEF box04-wall01 Wall {
  translation 0.39 -1.62 0
  name "box04-wall01"
  size 0.01 0.72 0.3
}
DEF box04-wall02 Wall {
  translation -0.37 -1.62 0
  name "box04-wall02"
  size 0.01 0.72 0.3
}
DEF box04-wall03 Wall {
  translation 0.0100073 -1.98 0
  rotation 0 0 1 1.5708
  name "box04-wall03"
  size 0.01 0.77 0.3
}
DEF box04-wall04 Wall {
  translation -0.149995 -1.26 0
  rotation 0 0 1 1.5708
  name "box04-wall04"
  size 0.01 0.44 0.3
}
DEF light01 CeilingSpotLight {
  translation 0.13 0.07 0.33
  name "light01"
  spotLightRadius 0.3
}
DEF light02 CeilingSpotLight {
  translation -0.11 -0.13 0.33
  name "light02"
  spotLightRadius 0.3
}
DEF light03 CeilingSpotLight {
  translation -0.06 -0.48 0.33
  name "light03"
  spotLightRadius 0.3
}
DEF light04 CeilingSpotLight {
  translation 0.31 -0.7 0.33
  name "light04"
  spotLightRadius 0.3
}
DEF light05 CeilingSpotLight {
  translation 0.18 -1.26 0.33
  rotation 0 1 0 0
  name "light05"
  spotLightRadius 0.3
}
DEF light06 CeilingSpotLight {
  translation -0.21 -1.51 0.33
  rotation 0 1 0 0
  name "light06"
  spotLightRadius 0.3
}
DEF light07 CeilingSpotLight {
  translation 0.11 -1.73 0.33
  rotation 0 1 0 0
  name "light07"
  spotLightRadius 0.3
}
Floor {
}
