#VRML_SIM R2022b utf8

EXTERNPROTO "https://raw.githubusercontent.com/cyberbotics/webots/R2022b/projects/objects/backgrounds/protos/TexturedBackground.proto"
EXTERNPROTO "https://raw.githubusercontent.com/cyberbotics/webots/R2022b/projects/objects/backgrounds/protos/TexturedBackgroundLight.proto"
EXTERNPROTO "https://raw.githubusercontent.com/cyberbotics/webots/R2022b/projects/objects/apartment_structure/protos/Wall.proto"
EXTERNPROTO "https://raw.githubusercontent.com/cyberbotics/webots/R2022b/projects/objects/floors/protos/Floor.proto"
EXTERNPROTO "https://raw.githubusercontent.com/cyberbotics/webots/R2022b/projects/objects/apartment_structure/protos/Ceiling.proto"
EXTERNPROTO "https://raw.githubusercontent.com/cyberbotics/webots/R2022b/projects/appearances/protos/Roughcast.proto"
EXTERNPROTO "https://raw.githubusercontent.com/cyberbotics/webots/R2022b/projects/objects/lights/protos/CeilingSpotLight.proto"

WorldInfo {
  basicTimeStep 0.1
}
Viewpoint {
  orientation 0.3628778442714662 -0.3272424556382911 -0.8724861290385736 4.474872756770491
  position 0.17794638259630285 -1.404861910097111 1.2126805680630506
}
TexturedBackground {
}
TexturedBackgroundLight {
  luminosity 0
}
DEF wall-e Robot {
  translation -0.00022252449409791188 0.002870748306721982 0.03500811994324181
  rotation 0.5804901661727087 -0.5757485874054912 -0.5757992107300623 2.0888458906350733
  scale 0.5 0.5 0.5
  children [
    DistanceSensor {
      translation 0 0.01 0.05
      rotation 0 1 0 -1.57
      children [
        DEF ddd Shape {
          appearance PBRAppearance {
            baseColor 0.333333 1 0.498039
          }
          geometry Sphere {
            radius 0.01
          }
        }
      ]
      name "distance_sensor_r"
      boundingObject USE ddd
      physics Physics {
      }
      lookupTable [
        0 10 0
        10 0 0
      ]
    }
    DistanceSensor {
      translation 0 0.01 -0.05
      rotation 0 1 0 1.57
      children [
        DEF ddd Shape {
          appearance PBRAppearance {
            baseColor 0.333333 1 0.498039
          }
          geometry Sphere {
            radius 0.01
          }
        }
      ]
      name "distance_sensor_l"
      boundingObject USE ddd
      physics Physics {
      }
      lookupTable [
        0 10 0
        10 0 0
      ]
    }
    DistanceSensor {
      translation 0.1 0.01 0
      rotation 1 0 0 1.57
      children [
        DEF ddd Shape {
          appearance PBRAppearance {
            baseColor 0.333333 1 0.498039
          }
          geometry Sphere {
            radius 0.01
          }
        }
      ]
      name "distance_sensor"
      boundingObject USE ddd
      physics Physics {
      }
      lookupTable [
        0 10 0
        10 0 0
      ]
    }
    BallJoint {
      jointParameters BallJointParameters {
        position -932.9705991131308
        anchor 0.07 -0.04 0
      }
      jointParameters2 JointParameters {
        position -535.6409406384979
      }
      jointParameters3 JointParameters {
        position 4095.4672480839736
      }
      endPoint Solid {
        translation 0.07373031104565243 -0.040048884922270905 -0.00046591406021116965
        rotation 0.9388883752326351 0.2830233083457557 -0.19592454105100163 1.3299634822223383
        children [
          DEF ball Shape {
            appearance PBRAppearance {
              baseColor 1 0 0
            }
            geometry Sphere {
              radius 0.03
            }
          }
        ]
        name "solid(2)"
        boundingObject USE ball
        physics Physics {
        }
        linearVelocity -0.0006654897183714947 0.03838115071969576 -5.127624085560499e-09
        angularVelocity -2.5587595048620146 -0.044368137987466534 -0.13677695733539388
      }
    }
    HingeJoint {
      jointParameters HingeJointParameters {
        position 51138.92738078391
        axis 0 0 1
        anchor -0.06 -0.04 -0.05
      }
      device [
        PositionSensor {
          name "l_p_s"
        }
        RotationalMotor {
          name "left_motor"
          acceleration 20
          controlPID 10 4 0
          maxVelocity 100
          minPosition -10
          maxPosition 100000000000
        }
      ]
      endPoint Solid {
        translation -0.05999189008855573 -0.039957707255758264 -0.0500017252624447
        rotation -4.977044892209937e-07 5.302348906056008e-07 0.9999999999997355 3.594455648489183
        children [
          DEF wheel Shape {
            appearance PBRAppearance {
              baseColor 1 0 0
            }
            geometry Cylinder {
              height 0.02
              radius 0.03
            }
          }
        ]
        name "solid(1)"
        boundingObject USE wheel
        physics Physics {
        }
        linearVelocity -0.0003199372392887625 0.03849939074445201 4.278362053528492e-06
        angularVelocity -2.566163300469056 -0.02132429463113033 -4.031619124841117e-06
      }
    }
    HingeJoint {
      jointParameters HingeJointParameters {
        position 25592.57218682084
        axis 0 0 1
        anchor -0.06 -0.04 0.05
      }
      device [
        PositionSensor {
          name "r_p_s"
        }
        RotationalMotor {
          name "right_motor"
          acceleration 20
          controlPID 10 4 0
          maxVelocity 100
          minPosition -10
          maxPosition 100000000000
        }
      ]
      endPoint Solid {
        translation -0.06002539908171084 -0.04001116831415267 0.050009869648899835
        rotation 2.299111499910177e-06 -3.220897846182152e-06 -0.9999999999921699 4.456869825344446
        children [
          DEF wheel Shape {
            appearance PBRAppearance {
              baseColor 1 0 0
            }
            geometry Cylinder {
              height 0.02
              radius 0.03
            }
          }
        ]
        boundingObject USE wheel
        physics Physics {
        }
        linearVelocity -0.000319938876445794 0.038499587754625295 4.2984887472063046e-06
        angularVelocity -2.5661633079979285 -0.021324294693665164 -4.031628845787939e-06
      }
    }
    DEF body Shape {
      appearance PBRAppearance {
      }
      geometry Box {
        size 0.2 0.07 0.1
      }
    }
  ]
  name "wall-e"
  boundingObject USE body
  physics DEF body Physics {
  }
  controller "wall-e-controller"
  supervisor TRUE
  linearVelocity -0.00033239786962838 0.03700011250933993 -0.0022073343333636887
  angularVelocity 0.0737376828846782 0.0014972821852239204 -0.0014154222660367403
}
DEF box01-floor Floor {
  name "box01-floor"
  size 0.43 0.69
}
DEF box01-wall01 Wall {
  translation -0.21 0 0
  name "box01-wall01"
  size 0.01 0.69 0.3
}
DEF box01-wall02 Wall {
  translation 5.19723e-15 0.34 0
  rotation 0 0 1 -1.5707953071795862
  name "box01-wall02"
  size 0.01 0.43 0.3
}
DEF box01-wall03 Wall {
  translation 0.21 0 0
  name "box01-wall03"
  size 0.01 0.69 0.3
}
DEF box01-ceiling Ceiling {
  translation 0 0 0.3
  name "box01-ceiling"
  size 0.43 0.69
  appearance Roughcast {
    colorOverride 0 0 0
    textureTransform TextureTransform {
      scale 10 10
    }
  }
}
DEF box02-wall01 Wall {
  translation -0.109997 -0.78 0
  rotation 0 0 1 1.5708
  name "box02-wall01"
  size 0.01 0.36 0.3
}
DEF box02-wall02 Wall {
  translation -0.29 -0.57 0
  name "box02-wall02"
  size 0.01 0.43 0.3
}
DEF box02-wall03 Wall {
  translation 0.39 -0.57 0
  name "box02-wall03"
  size 0.01 0.43 0.3
}
DEF box02-wall04 Wall {
  translation -0.25 -0.35 2.87698e-09
  rotation -9.58979e-09 9.58976e-09 -1 -1.5707953071795862
  name "box02-wall04"
  size 0.01 0.08 0.3
}
DEF box02-wall05 Wall {
  translation 0.3 -0.35 2.87698e-09
  rotation -9.58979e-09 9.58976e-09 -1 -1.5707953071795862
  name "box02-wall05"
  size 0.01 0.18 0.3
}
DEF box02-floor Floor {
  translation 0.048 -0.56 0
  name "box02-floor"
  size 0.69 0.43
}
DEF box02-ceiling Ceiling {
  translation 0.048 -0.56 0.3
  name "box02-ceiling"
  size 0.69 0.43
  appearance Roughcast {
    colorOverride 0 0 0
    textureTransform TextureTransform {
      scale 10 10
    }
  }
}
DEF box03-wall01 Wall {
  translation 0.07 -1.02 0
  name "box03-wall01"
  size 0.01 0.48 0.3
}
DEF box03-wall02 Wall {
  translation 0.39 -1.02 0
  name "box03-wall02"
  size 0.01 0.48 0.3
}
DEF box03-floor Floor {
  translation 0.23 -1.014 0
  name "box03-floor"
  size 0.33 0.48
}
DEF box03-ceiling Ceiling {
  translation 0.23 -1.014 0.3
  name "box03-ceiling"
  size 0.33 0.48
  appearance Roughcast {
    colorOverride 0 0 0
    textureTransform TextureTransform {
      scale 10 10
    }
  }
}
DEF box04-wall01 Wall {
  translation 0.39 -1.62 0
  name "box04-wall01"
  size 0.01 0.72 0.3
}
DEF box04-wall02 Wall {
  translation -0.37 -1.62 0
  name "box04-wall02"
  size 0.01 0.72 0.3
}
DEF box04-wall03 Wall {
  translation 0.0100073 -1.98 0
  rotation 0 0 1 1.5708
  name "box04-wall03"
  size 0.01 0.77 0.3
}
DEF box04-wall04 Wall {
  translation -0.149995 -1.26 0
  rotation 0 0 1 1.5708
  name "box04-wall04"
  size 0.01 0.44 0.3
}
DEF box04-floor Floor {
  translation 0.01 -1.61 0
  name "box04-floor"
  size 0.77 0.73
}
DEF box04-ceiling Ceiling {
  translation 0.01 -1.61 0.3
  name "box04-ceiling"
  size 0.77 0.73
  appearance Roughcast {
    colorOverride 0 0 0
    textureTransform TextureTransform {
      scale 10 10
    }
  }
}
DEF light01 CeilingSpotLight {
  translation 0.13 0.07 0.33
  name "light01"
  spotLightRadius 0.3
}
DEF light02 CeilingSpotLight {
  translation -0.11 -0.13 0.33
  name "light02"
  spotLightRadius 0.3
}
DEF light03 CeilingSpotLight {
  translation -0.06 -0.48 0.33
  name "light03"
  spotLightRadius 0.3
}
DEF light04 CeilingSpotLight {
  translation 0.31 -0.7 0.33
  name "light04"
  spotLightRadius 0.3
}
DEF light05 CeilingSpotLight {
  translation 0.18 -1.26 0.33
  rotation 0 1 0 0
  name "light05"
  spotLightRadius 0.3
}
DEF light06 CeilingSpotLight {
  translation -0.21 -1.51 0.33
  rotation 0 1 0 0
  name "light06"
  spotLightRadius 0.3
}
DEF light07 CeilingSpotLight {
  translation 0.11 -1.73 0.33
  rotation 0 1 0 0
  name "light07"
  spotLightRadius 0.3
}
