#VRML_SIM R2022b utf8

EXTERNPROTO "https://raw.githubusercontent.com/cyberbotics/webots/R2022b/projects/objects/backgrounds/protos/TexturedBackground.proto"
EXTERNPROTO "https://raw.githubusercontent.com/cyberbotics/webots/R2022b/projects/objects/backgrounds/protos/TexturedBackgroundLight.proto"
EXTERNPROTO "https://raw.githubusercontent.com/cyberbotics/webots/R2022b/projects/objects/apartment_structure/protos/Wall.proto"
EXTERNPROTO "https://raw.githubusercontent.com/cyberbotics/webots/R2022b/projects/objects/lights/protos/CeilingSpotLight.proto"
EXTERNPROTO "https://raw.githubusercontent.com/cyberbotics/webots/R2022b/projects/objects/floors/protos/Floor.proto"

WorldInfo {
  basicTimeStep 24
}
Viewpoint {
  orientation 0.26603065584747126 -0.18546266792834287 -0.9459552256604249 4.3075902421565955
  position 0.4965894038991413 -1.905534265532483 0.8721954446862882
}
TexturedBackground {
}
TexturedBackgroundLight {
  luminosity 0
}
DEF wall-e Robot {
  translation -0.0328028 -0.0410983 0.0558048
  rotation 0.6793843993718797 -0.5090201122601862 -0.5285218663449391 1.9679561460802681
  scale 0.5 0.5 0.5
  children [
    DistanceSensor {
      translation 0 0.01 0.05
      rotation 0 1 0 -1.57
      children [
        DEF ddd Shape {
          appearance PBRAppearance {
            baseColor 0.333333 1 0.498039
          }
          geometry Sphere {
            radius 0.01
          }
        }
      ]
      name "distance_sensor_r"
      boundingObject USE ddd
      physics Physics {
      }
      lookupTable [
        0 10 0
        1 0 0
      ]
      type "sonar"
    }
    DistanceSensor {
      translation 0 0.01 -0.05
      rotation 0 1 0 1.57
      children [
        DEF ddd Shape {
          appearance PBRAppearance {
            baseColor 0.333333 1 0.498039
          }
          geometry Sphere {
            radius 0.01
          }
        }
      ]
      name "distance_sensor_l"
      boundingObject USE ddd
      physics Physics {
      }
      lookupTable [
        0 10 0
        1 0 0
      ]
      type "sonar"
    }
    DistanceSensor {
      translation 0.1 0.01 0
      rotation 1 0 0 1.57
      children [
        DEF ddd Shape {
          appearance PBRAppearance {
            baseColor 0.333333 1 0.498039
          }
          geometry Sphere {
            radius 0.01
          }
        }
      ]
      name "distance_sensor"
      boundingObject USE ddd
      physics Physics {
      }
      lookupTable [
        0 10 0
        1 0 0
      ]
      type "sonar"
    }
    BallJoint {
      jointParameters BallJointParameters {
        position -953.3950115013909
        anchor 0.07 -0.04 0
      }
      jointParameters2 JointParameters {
        position -532.41510578252
      }
      jointParameters3 JointParameters {
        position 4052.294817845134
      }
      endPoint Solid {
        translation 0.0716406516366247 -0.043273202421160666 -0.0009713599680891683
        rotation -0.709903517533858 0.09621406943968132 0.697696100487104 4.440762543208873
        children [
          DEF ball Shape {
            appearance PBRAppearance {
              baseColor 1 0 0
            }
            geometry Sphere {
              radius 0.03
            }
          }
        ]
        name "solid(2)"
        boundingObject USE ball
        physics Physics {
        }
      }
    }
    HingeJoint {
      jointParameters HingeJointParameters {
        position 51014.04823927189
        axis 0 0 1
        anchor -0.06 -0.04 -0.05
      }
      device [
        PositionSensor {
          name "l_p_s"
        }
        RotationalMotor {
          name "left_motor"
          acceleration 20
          controlPID 10 4 0
          maxVelocity 100
          minPosition -10
          maxPosition 100000000000
        }
      ]
      endPoint Solid {
        translation -0.060024141197354004 -0.0399643398055327 -0.0500017252624447
        rotation -7.926252090688551e-07 3.584915443632182e-07 0.9999999999996217 4.379020280059369
        children [
          DEF wheel Shape {
            appearance PBRAppearance {
              baseColor 1 0 0
            }
            geometry Cylinder {
              height 0.02
              radius 0.03
            }
          }
        ]
        name "solid(1)"
        boundingObject USE wheel
        physics Physics {
        }
      }
    }
    HingeJoint {
      jointParameters HingeJointParameters {
        position 25467.693017689628
        axis 0 0 1
        anchor -0.06 -0.04 0.05
      }
      device [
        PositionSensor {
          name "r_p_s"
        }
        RotationalMotor {
          name "right_motor"
          acceleration 20
          controlPID 10 4 0
          maxVelocity 100
          minPosition -10
          maxPosition 100000000000
        }
      ]
      endPoint Solid {
        translation -0.06001008493533596 -0.040025848378518504 0.050009869648899835
        rotation 2.7522346986011752e-06 -1.7201221720271667e-06 -0.9999999999947332 3.6723328129684396
        children [
          DEF wheel Shape {
            appearance PBRAppearance {
              baseColor 1 0 0
            }
            geometry Cylinder {
              height 0.02
              radius 0.03
            }
          }
        ]
        boundingObject USE wheel
        physics Physics {
        }
      }
    }
    DEF body Shape {
      appearance PBRAppearance {
      }
      geometry Box {
        size 0.2 0.07 0.1
      }
    }
  ]
  name "wall-e"
  boundingObject USE body
  physics DEF body Physics {
  }
  controller "wall-e-controller"
  supervisor TRUE
}
DEF box01-wall01 Wall {
  translation -0.21 0 0
  name "box01-wall01"
  size 0.01 0.69 0.3
}
DEF box01-wall02 Wall {
  translation 5.19723e-15 0.34 0
  rotation 0 0 1 -1.5707953071795862
  name "box01-wall02"
  size 0.01 0.43 0.3
}
DEF box01-wall03 Wall {
  translation 0.21 0 0
  name "box01-wall03"
  size 0.01 0.69 0.3
}
DEF box02-wall01 Wall {
  translation -0.109997 -0.78 0
  rotation 0 0 1 1.5708
  name "box02-wall01"
  size 0.01 0.36 0.3
}
DEF box02-wall02 Wall {
  translation -0.29 -0.57 0
  name "box02-wall02"
  size 0.01 0.43 0.3
}
DEF box02-wall03 Wall {
  translation 0.39 -0.57 0
  name "box02-wall03"
  size 0.01 0.43 0.3
}
DEF box02-wall04 Wall {
  translation -0.25 -0.35 2.87698e-09
  rotation -9.58979e-09 9.58976e-09 -1 -1.5707953071795862
  name "box02-wall04"
  size 0.01 0.08 0.3
}
DEF box02-wall05 Wall {
  translation 0.3 -0.35 2.87698e-09
  rotation -9.58979e-09 9.58976e-09 -1 -1.5707953071795862
  name "box02-wall05"
  size 0.01 0.18 0.3
}
DEF box03-wall01 Wall {
  translation 0.07 -1.02 0
  name "box03-wall01"
  size 0.01 0.48 0.3
}
DEF box03-wall02 Wall {
  translation 0.39 -1.02 0
  name "box03-wall02"
  size 0.01 0.48 0.3
}
DEF box04-wall01 Wall {
  translation 0.39 -1.62 0
  name "box04-wall01"
  size 0.01 0.72 0.3
}
DEF box04-wall02 Wall {
  translation -0.37 -1.62 0
  name "box04-wall02"
  size 0.01 0.72 0.3
}
DEF box04-wall03 Wall {
  translation 0.0100073 -1.98 0
  rotation 0 0 1 1.5708
  name "box04-wall03"
  size 0.01 0.77 0.3
}
DEF box04-wall04 Wall {
  translation -0.149995 -1.26 0
  rotation 0 0 1 1.5708
  name "box04-wall04"
  size 0.01 0.44 0.3
}
DEF light01 CeilingSpotLight {
  translation 0.13 0.07 0.33
  name "light01"
  spotLightRadius 0.3
}
DEF light02 CeilingSpotLight {
  translation -0.11 -0.13 0.33
  name "light02"
  spotLightRadius 0.3
}
DEF light03 CeilingSpotLight {
  translation -0.06 -0.48 0.33
  name "light03"
  spotLightRadius 0.3
}
DEF light04 CeilingSpotLight {
  translation 0.31 -0.7 0.33
  name "light04"
  spotLightRadius 0.3
}
DEF light05 CeilingSpotLight {
  translation 0.18 -1.26 0.33
  rotation 0 1 0 0
  name "light05"
  spotLightRadius 0.3
}
DEF light06 CeilingSpotLight {
  translation -0.21 -1.51 0.33
  rotation 0 1 0 0
  name "light06"
  spotLightRadius 0.3
}
DEF light07 CeilingSpotLight {
  translation 0.11 -1.73 0.33
  rotation 0 1 0 0
  name "light07"
  spotLightRadius 0.3
}
Floor {
}
