#VRML_SIM R2022b utf8

EXTERNPROTO "https://raw.githubusercontent.com/cyberbotics/webots/R2022b/projects/objects/backgrounds/protos/TexturedBackground.proto"
EXTERNPROTO "https://raw.githubusercontent.com/cyberbotics/webots/R2022b/projects/objects/backgrounds/protos/TexturedBackgroundLight.proto"
EXTERNPROTO "https://raw.githubusercontent.com/cyberbotics/webots/R2022b/projects/objects/apartment_structure/protos/Wall.proto"
EXTERNPROTO "https://raw.githubusercontent.com/cyberbotics/webots/R2022b/projects/objects/lights/protos/CeilingSpotLight.proto"
EXTERNPROTO "https://raw.githubusercontent.com/cyberbotics/webots/R2022b/projects/objects/floors/protos/Floor.proto"

WorldInfo {
  basicTimeStep 24
}
Viewpoint {
  orientation -0.33399104861230977 0.2264403516919374 0.9149725386985567 2.0311157233579116
  position 0.4563339349850965 -2.0582256901364446 0.8067091656071911
}
TexturedBackground {
}
TexturedBackgroundLight {
  luminosity 0
}
DEF wall-e Robot {
  translation 0.1877546396919736 -1.4558277966859214 0.06963732052200244
  rotation -0.5585661699929936 0.5863606153788549 0.5866728751799327 -2.123812452519222
  children [
    LightSensor {
      translation 0 0.04 0
      rotation 0 0 -1 -1.5708053071795867
      children [
        Shape {
          appearance PBRAppearance {
            baseColor 0 0 0
          }
          geometry Box {
            size 0.01 0.2 0.14
          }
        }
      ]
      name "panel"
      boundingObject Box {
        size 0.01 0.2 0.1
      }
      lookupTable [
        0 0 0
        10 10 0
      ]
    }
    LightSensor {
      translation 0.19 0.02 0.12
      rotation 0 0 1 1.5708
      children [
        Shape {
          appearance PBRAppearance {
            baseColor 0 0 1
          }
          geometry Box {
            size 0.005 0.005 0.005
          }
        }
      ]
      name "light_sensor_r"
      boundingObject Box {
        size 0.005 0.005 0.005
      }
      physics Physics {
      }
      lookupTable [
        0 0 0
        10 10 0
      ]
    }
    LightSensor {
      translation 0.19 0.02 0
      rotation 0 0 1 1.5708
      children [
        Shape {
          appearance PBRAppearance {
            baseColor 0 0 1
          }
          geometry Box {
            size 0.005 0.005 0.005
          }
        }
      ]
      name "light_sensor_c"
      boundingObject Box {
        size 0.005 0.005 0.005
      }
      physics Physics {
      }
      lookupTable [
        0 0 0
        10 10 0
      ]
    }
    LightSensor {
      translation 0.19 0.02 -0.12
      rotation 0 0 1 1.5708
      children [
        Shape {
          appearance PBRAppearance {
            baseColor 0 0 1
          }
          geometry Box {
            size 0.005 0.005 0.005
          }
        }
      ]
      name "light_sensor_l"
      boundingObject Box {
        size 0.005 0.005 0.005
      }
      physics Physics {
      }
      lookupTable [
        0 0 0
        10 10 0
      ]
    }
    DistanceSensor {
      translation 0 0.01 0.05
      rotation 0 1 0 -1.57
      children [
        DEF ddd Shape {
          appearance PBRAppearance {
            baseColor 0.333333 1 0.498039
          }
          geometry Sphere {
            radius 0.01
          }
        }
      ]
      name "distance_sensor_r"
      boundingObject USE ddd
      physics Physics {
      }
      lookupTable [
        0 10 0
        1 0 0
      ]
      type "sonar"
    }
    DistanceSensor {
      translation 0 0.01 -0.05
      rotation 0 1 0 1.57
      children [
        DEF ddd Shape {
          appearance PBRAppearance {
            baseColor 0.333333 1 0.498039
          }
          geometry Sphere {
            radius 0.01
          }
        }
      ]
      name "distance_sensor_l"
      boundingObject USE ddd
      physics Physics {
      }
      lookupTable [
        0 10 0
        1 0 0
      ]
      type "sonar"
    }
    DistanceSensor {
      translation 0.1 0.01 0
      rotation 1 0 0 1.57
      children [
        DEF ddd Shape {
          appearance PBRAppearance {
            baseColor 0.333333 1 0.498039
          }
          geometry Sphere {
            radius 0.01
          }
        }
      ]
      name "distance_sensor"
      boundingObject USE ddd
      physics Physics {
      }
      lookupTable [
        0 10 0
        1 0 0
      ]
      type "sonar"
    }
    BallJoint {
      jointParameters BallJointParameters {
        position -937.6044182158305
        anchor 0.07 -0.04 0
      }
      jointParameters2 JointParameters {
        position -526.8060518713777
      }
      jointParameters3 JointParameters {
        position 4047.5136911120926
      }
      endPoint Solid {
        translation 0.067601131035957 -0.040667902354075275 0.00302947389383873
        rotation -0.10843978962620202 0.9224609976104692 0.37054894401863137 -2.2249888465164194
        children [
          DEF ball Shape {
            appearance PBRAppearance {
              baseColor 1 0 0
            }
            geometry Sphere {
              radius 0.03
            }
          }
        ]
        name "solid(2)"
        boundingObject USE ball
        physics Physics {
        }
        linearVelocity -0.0007332488996745007 -0.07457312674694216 -8.38689121820263e-05
        angularVelocity 2.486003494196265 -0.0241513564541661 -1.3911126323448157
      }
    }
    HingeJoint {
      jointParameters HingeJointParameters {
        position 50897.569609883394
        axis 0 0 1
        anchor -0.06 -0.04 -0.05
      }
      device [
        PositionSensor {
          name "l_p_s"
        }
        RotationalMotor {
          name "left_motor"
          acceleration 20
          controlPID 10 4 0
          maxVelocity 100
          minPosition -10
          maxPosition 100000000000
        }
      ]
      endPoint Solid {
        translation -0.05998397140676908 -0.04003973176392754 -0.05000184065243736
        rotation 4.508228943553718e-06 -4.1851452708168964e-06 -0.9999999999810802 5.282829754866162
        children [
          DEF wheel Shape {
            appearance PBRAppearance {
              baseColor 1 0 0
            }
            geometry Cylinder {
              height 0.02
              radius 0.03
            }
          }
        ]
        name "solid(1)"
        boundingObject USE wheel
        physics Physics {
        }
        linearVelocity -0.003985312206552848 -0.08052968835062053 2.9246634040349717e-05
        angularVelocity 2.6845590465448854 -0.13293122467696156 -0.0007825850814840301
      }
    }
    HingeJoint {
      jointParameters HingeJointParameters {
        position 25351.214373744166
        axis 0 0 1
        anchor -0.06 -0.04 0.05
      }
      device [
        PositionSensor {
          name "r_p_s"
        }
        RotationalMotor {
          name "right_motor"
          acceleration 20
          controlPID 10 4 0
          maxVelocity 100
          minPosition -10
          maxPosition 100000000000
        }
      ]
      endPoint Solid {
        translation -0.05998387028137321 -0.03997589609372924 0.05001002093556352
        rotation 1.935068347461595e-06 -3.6669885117324033e-06 0.9999999999914043 5.515358516657285
        children [
          DEF wheel Shape {
            appearance PBRAppearance {
              baseColor 1 0 0
            }
            geometry Cylinder {
              height 0.02
              radius 0.03
            }
          }
        ]
        boundingObject USE wheel
        physics Physics {
        }
        linearVelocity -0.0039862044925876765 -0.08054840468553058 1.1865503201660137e-05
        angularVelocity 2.6845600993186833 -0.13293127761478632 -0.0007826009741320282
      }
    }
    DEF body Shape {
      appearance PBRAppearance {
      }
      geometry Box {
        size 0.2 0.07 0.14
      }
    }
  ]
  name "wall-e"
  boundingObject USE body
  physics DEF body Physics {
  }
  controller "wall-e-controller"
  supervisor TRUE
  linearVelocity -0.004183015490051171 -0.08246659016800327 -0.002806980151035464
  angularVelocity 0.047778076193517885 -0.0026113302033533396 -0.0015270774361646384
}
DEF box01-wall01 Wall {
  translation -0.21 0 0
  name "box01-wall01"
  size 0.01 0.69 0.3
}
DEF box01-wall02 Wall {
  translation 5.19723e-15 0.34 0
  rotation 0 0 1 -1.5707953071795862
  name "box01-wall02"
  size 0.01 0.43 0.3
}
DEF box01-wall03 Wall {
  translation 0.21 0 0
  name "box01-wall03"
  size 0.01 0.69 0.3
}
DEF box02-wall01 Wall {
  translation -0.109997 -0.78 0
  rotation 0 0 1 1.5708
  name "box02-wall01"
  size 0.01 0.36 0.3
}
DEF box02-wall02 Wall {
  translation -0.29 -0.57 0
  name "box02-wall02"
  size 0.01 0.43 0.3
}
DEF box02-wall03 Wall {
  translation 0.39 -0.57 0
  name "box02-wall03"
  size 0.01 0.43 0.3
}
DEF box02-wall04 Wall {
  translation -0.25 -0.35 2.87698e-09
  rotation -9.58979e-09 9.58976e-09 -1 -1.5707953071795862
  name "box02-wall04"
  size 0.01 0.08 0.3
}
DEF box02-wall05 Wall {
  translation 0.3 -0.35 2.87698e-09
  rotation -9.58979e-09 9.58976e-09 -1 -1.5707953071795862
  name "box02-wall05"
  size 0.01 0.18 0.3
}
DEF box03-wall01 Wall {
  translation 0.07 -1.02 0
  name "box03-wall01"
  size 0.01 0.48 0.3
}
DEF box03-wall02 Wall {
  translation 0.39 -1.02 0
  name "box03-wall02"
  size 0.01 0.48 0.3
}
DEF box04-wall01 Wall {
  translation 0.39 -1.62 0
  name "box04-wall01"
  size 0.01 0.72 0.3
}
DEF box04-wall02 Wall {
  translation -0.37 -1.62 0
  name "box04-wall02"
  size 0.01 0.72 0.3
}
DEF box04-wall03 Wall {
  translation 0.0100073 -1.98 0
  rotation 0 0 1 1.5708
  name "box04-wall03"
  size 0.01 0.77 0.3
}
DEF box04-wall04 Wall {
  translation -0.149995 -1.26 0
  rotation 0 0 1 1.5708
  name "box04-wall04"
  size 0.01 0.44 0.3
}
DEF light01 CeilingSpotLight {
  translation 0.13 0.07 0.33
  name "light01"
  spotLightRadius 0.3
}
DEF light02 CeilingSpotLight {
  translation -0.11 -0.13 0.33
  name "light02"
  spotLightRadius 0.3
}
DEF light03 CeilingSpotLight {
  translation -0.06 -0.48 0.33
  name "light03"
  spotLightRadius 0.3
}
DEF light04 CeilingSpotLight {
  translation 0.31 -0.7 0.33
  name "light04"
  spotLightRadius 0.3
}
DEF light05 CeilingSpotLight {
  translation 0.18 -1.26 0.33
  rotation 0 1 0 0
  name "light05"
  spotLightRadius 0.3
}
DEF light06 CeilingSpotLight {
  translation -0.21 -1.51 0.33
  rotation 0 1 0 0
  name "light06"
  spotLightRadius 0.3
}
DEF light07 CeilingSpotLight {
  translation 0.11 -1.73 0.33
  rotation 0 1 0 0
  name "light07"
  spotLightRadius 0.3
}
Floor {
}
