#VRML_SIM R2022b utf8

EXTERNPROTO "https://raw.githubusercontent.com/cyberbotics/webots/R2022b/projects/objects/backgrounds/protos/TexturedBackground.proto"
EXTERNPROTO "https://raw.githubusercontent.com/cyberbotics/webots/R2022b/projects/objects/backgrounds/protos/TexturedBackgroundLight.proto"
EXTERNPROTO "https://raw.githubusercontent.com/cyberbotics/webots/R2022b/projects/objects/apartment_structure/protos/Wall.proto"
EXTERNPROTO "https://raw.githubusercontent.com/cyberbotics/webots/R2022b/projects/objects/lights/protos/CeilingSpotLight.proto"
EXTERNPROTO "https://raw.githubusercontent.com/cyberbotics/webots/R2022b/projects/objects/floors/protos/Floor.proto"

WorldInfo {
  basicTimeStep 24
}
Viewpoint {
  orientation 0.47709969951543596 0.7282092115658424 -0.49202359792283845 1.8533264836107821
  position -0.07279707642363838 -0.039388100471818226 1.5931860803445044
}
TexturedBackground {
}
TexturedBackgroundLight {
  luminosity 0
}
DEF wall-e Robot {
  translation -0.0037980379540945774 -0.23234041665427596 0.03484136019961129
  rotation 0.6755880761812605 -0.5199347889360195 -0.5227318304597112 1.9557653649742464
  scale 0.5 0.5 0.5
  children [
    LightSensor {
      translation 0 0.04 0
      rotation 0 0 -1 -1.5708053071795867
      children [
        Shape {
          appearance PBRAppearance {
            baseColor 0 0 0
          }
          geometry Box {
            size 0.01 0.2 0.1
          }
        }
      ]
      name "panel"
      boundingObject Box {
        size 0.01 0.2 0.1
      }
      lookupTable [
        0 0 0
        10 10 0
      ]
    }
    LightSensor {
      translation 0.19 0.02 0.12
      rotation 0 0 1 1.5708
      children [
        Shape {
          appearance PBRAppearance {
            baseColor 0 0 1
          }
          geometry Box {
            size 0.005 0.005 0.005
          }
        }
      ]
      name "light_sensor_r"
      boundingObject Box {
        size 0.005 0.005 0.005
      }
      physics Physics {
      }
      lookupTable [
        0 0 0
        10 10 0
      ]
    }
    LightSensor {
      translation 0.19 0.02 0
      rotation 0 0 1 1.5708
      children [
        Shape {
          appearance PBRAppearance {
            baseColor 0 0 1
          }
          geometry Box {
            size 0.005 0.005 0.005
          }
        }
      ]
      name "light_sensor_c"
      boundingObject Box {
        size 0.005 0.005 0.005
      }
      physics Physics {
      }
      lookupTable [
        0 0 0
        10 10 0
      ]
    }
    LightSensor {
      translation 0.19 0.02 -0.12
      rotation 0 0 1 1.5708
      children [
        Shape {
          appearance PBRAppearance {
            baseColor 0 0 1
          }
          geometry Box {
            size 0.005 0.005 0.005
          }
        }
      ]
      name "light_sensor_l"
      boundingObject Box {
        size 0.005 0.005 0.005
      }
      physics Physics {
      }
      lookupTable [
        0 0 0
        10 10 0
      ]
    }
    DistanceSensor {
      translation 0 0.01 0.05
      rotation 0 1 0 -1.57
      children [
        DEF ddd Shape {
          appearance PBRAppearance {
            baseColor 0.333333 1 0.498039
          }
          geometry Sphere {
            radius 0.01
          }
        }
      ]
      name "distance_sensor_r"
      boundingObject USE ddd
      physics Physics {
      }
      lookupTable [
        0 10 0
        1 0 0
      ]
      type "sonar"
    }
    DistanceSensor {
      translation 0 0.01 -0.05
      rotation 0 1 0 1.57
      children [
        DEF ddd Shape {
          appearance PBRAppearance {
            baseColor 0.333333 1 0.498039
          }
          geometry Sphere {
            radius 0.01
          }
        }
      ]
      name "distance_sensor_l"
      boundingObject USE ddd
      physics Physics {
      }
      lookupTable [
        0 10 0
        1 0 0
      ]
      type "sonar"
    }
    DistanceSensor {
      translation 0.1 0.01 0
      rotation 1 0 0 1.57
      children [
        DEF ddd Shape {
          appearance PBRAppearance {
            baseColor 0.333333 1 0.498039
          }
          geometry Sphere {
            radius 0.01
          }
        }
      ]
      name "distance_sensor"
      boundingObject USE ddd
      physics Physics {
      }
      lookupTable [
        0 10 0
        1 0 0
      ]
      type "sonar"
    }
    BallJoint {
      jointParameters BallJointParameters {
        position -950.2913409390677
        anchor 0.07 -0.04 0
      }
      jointParameters2 JointParameters {
        position -532.3955596935662
      }
      jointParameters3 JointParameters {
        position 4049.073422764383
      }
      endPoint Solid {
        translation 0.07382407348621917 -0.039619204635839095 0.0004680668607916355
        rotation -0.9778765060646123 -0.1794613980668629 0.10747625547418961 -0.8009318399228391
        children [
          DEF ball Shape {
            appearance PBRAppearance {
              baseColor 1 0 0
            }
            geometry Sphere {
              radius 0.03
            }
          }
        ]
        name "solid(2)"
        boundingObject USE ball
        physics Physics {
        }
        linearVelocity 0.00955601194424167 -0.03784289784637701 7.982937257082854e-06
        angularVelocity 2.5227931109882182 0.6370583836524167 -0.1736608479636786
      }
    }
    HingeJoint {
      jointParameters HingeJointParameters {
        position 50975.10487957734
        axis 0 0 1
        anchor -0.06 -0.04 -0.05
      }
      device [
        PositionSensor {
          name "l_p_s"
        }
        RotationalMotor {
          name "left_motor"
          acceleration 20
          controlPID 10 4 0
          maxVelocity 100
          minPosition -10
          maxPosition 100000000000
        }
      ]
      endPoint Solid {
        translation -0.05997396817549192 -0.039965695612643404 -0.0500017252624447
        rotation -3.5453142879059893e-07 6.13609909162284e-07 0.999999999999749 3.134772428584465
        children [
          DEF wheel Shape {
            appearance PBRAppearance {
              baseColor 1 0 0
            }
            geometry Cylinder {
              height 0.02
              radius 0.03
            }
          }
        ]
        name "solid(1)"
        boundingObject USE wheel
        physics Physics {
        }
        linearVelocity 0.009682202445387745 -0.03721315426793523 -3.4120817400195336e-06
        angularVelocity 2.4807714538545915 0.6454339633195826 -7.04176947817071e-05
      }
    }
    HingeJoint {
      jointParameters HingeJointParameters {
        position 25428.749657985158
        axis 0 0 1
        anchor -0.06 -0.04 0.05
      }
      device [
        PositionSensor {
          name "r_p_s"
        }
        RotationalMotor {
          name "right_motor"
          acceleration 20
          controlPID 10 4 0
          maxVelocity 100
          minPosition -10
          maxPosition 100000000000
        }
      ]
      endPoint Solid {
        translation -0.06002771742815102 -0.039998739536014405 0.050009869648899835
        rotation 1.8863471573644515e-06 -4.588002170627905e-06 -0.999999999987696 4.916580674351453
        children [
          DEF wheel Shape {
            appearance PBRAppearance {
              baseColor 1 0 0
            }
            geometry Cylinder {
              height 0.02
              radius 0.03
            }
          }
        ]
        boundingObject USE wheel
        physics Physics {
        }
        linearVelocity 0.009680747637498838 -0.037209087279875756 -3.732793059683927e-07
        angularVelocity 2.480771428015558 0.645433958635997 -7.040313575780522e-05
      }
    }
    DEF body Shape {
      appearance PBRAppearance {
      }
      geometry Box {
        size 0.2 0.07 0.1
      }
    }
  ]
  name "wall-e"
  boundingObject USE body
  physics DEF body Physics {
  }
  controller "wall-e-controller"
  supervisor TRUE
  linearVelocity 0.009290792860735175 -0.03571324280222735 0.002316250933713498
  angularVelocity -0.07383466909656668 -0.020589120764949245 0.0008459989978468567
}
DEF box01-wall01 Wall {
  translation -0.21 0 0
  name "box01-wall01"
  size 0.01 0.69 0.3
}
DEF box01-wall02 Wall {
  translation 5.19723e-15 0.34 0
  rotation 0 0 1 -1.5707953071795862
  name "box01-wall02"
  size 0.01 0.43 0.3
}
DEF box01-wall03 Wall {
  translation 0.21 0 0
  name "box01-wall03"
  size 0.01 0.69 0.3
}
DEF box02-wall01 Wall {
  translation -0.109997 -0.78 0
  rotation 0 0 1 1.5708
  name "box02-wall01"
  size 0.01 0.36 0.3
}
DEF box02-wall02 Wall {
  translation -0.29 -0.57 0
  name "box02-wall02"
  size 0.01 0.43 0.3
}
DEF box02-wall03 Wall {
  translation 0.39 -0.57 0
  name "box02-wall03"
  size 0.01 0.43 0.3
}
DEF box02-wall04 Wall {
  translation -0.25 -0.35 2.87698e-09
  rotation -9.58979e-09 9.58976e-09 -1 -1.5707953071795862
  name "box02-wall04"
  size 0.01 0.08 0.3
}
DEF box02-wall05 Wall {
  translation 0.3 -0.35 2.87698e-09
  rotation -9.58979e-09 9.58976e-09 -1 -1.5707953071795862
  name "box02-wall05"
  size 0.01 0.18 0.3
}
DEF box03-wall01 Wall {
  translation 0.07 -1.02 0
  name "box03-wall01"
  size 0.01 0.48 0.3
}
DEF box03-wall02 Wall {
  translation 0.39 -1.02 0
  name "box03-wall02"
  size 0.01 0.48 0.3
}
DEF box04-wall01 Wall {
  translation 0.39 -1.62 0
  name "box04-wall01"
  size 0.01 0.72 0.3
}
DEF box04-wall02 Wall {
  translation -0.37 -1.62 0
  name "box04-wall02"
  size 0.01 0.72 0.3
}
DEF box04-wall03 Wall {
  translation 0.0100073 -1.98 0
  rotation 0 0 1 1.5708
  name "box04-wall03"
  size 0.01 0.77 0.3
}
DEF box04-wall04 Wall {
  translation -0.149995 -1.26 0
  rotation 0 0 1 1.5708
  name "box04-wall04"
  size 0.01 0.44 0.3
}
DEF light01 CeilingSpotLight {
  translation 0.13 0.07 0.33
  name "light01"
  spotLightRadius 0.3
}
DEF light02 CeilingSpotLight {
  translation -0.11 -0.13 0.33
  name "light02"
  spotLightRadius 0.3
}
DEF light03 CeilingSpotLight {
  translation -0.06 -0.48 0.33
  name "light03"
  spotLightRadius 0.3
}
DEF light04 CeilingSpotLight {
  translation 0.31 -0.7 0.33
  name "light04"
  spotLightRadius 0.3
}
DEF light05 CeilingSpotLight {
  translation 0.18 -1.26 0.33
  rotation 0 1 0 0
  name "light05"
  spotLightRadius 0.3
}
DEF light06 CeilingSpotLight {
  translation -0.21 -1.51 0.33
  rotation 0 1 0 0
  name "light06"
  spotLightRadius 0.3
}
DEF light07 CeilingSpotLight {
  translation 0.11 -1.73 0.33
  rotation 0 1 0 0
  name "light07"
  spotLightRadius 0.3
}
Floor {
}
