#VRML_SIM R2022b utf8

EXTERNPROTO "https://raw.githubusercontent.com/cyberbotics/webots/R2022b/projects/objects/backgrounds/protos/TexturedBackground.proto"
EXTERNPROTO "https://raw.githubusercontent.com/cyberbotics/webots/R2022b/projects/objects/backgrounds/protos/TexturedBackgroundLight.proto"
EXTERNPROTO "https://raw.githubusercontent.com/cyberbotics/webots/R2022b/projects/objects/floors/protos/RectangleArena.proto"
EXTERNPROTO "https://raw.githubusercontent.com/cyberbotics/webots/R2022b/projects/objects/apartment_structure/protos/Wall.proto"
EXTERNPROTO "https://raw.githubusercontent.com/cyberbotics/webots/R2022b/projects/objects/lights/protos/CeilingSpotLight.proto"

WorldInfo {
}
Viewpoint {
  orientation -0.11819607195838217 0.38669505753009936 0.9146018921123016 0.645078923611152
  position -0.4654994588294886 -0.8980881426963748 0.18845185248957907
}
TexturedBackground {
}
TexturedBackgroundLight {
  luminosity 0
}
DEF myrobot Robot {
  translation 0.0010912590567937251 -0.2490469227093722 0.06875598459946554
  rotation 0.5802247332770055 -0.5715598860429092 -0.5802228499122078 2.1032104528830065
  children [
    DistanceSensor {
      translation 0 0.01 0.05
      rotation 0 1 0 -1.57
      children [
        DEF ddd Shape {
          appearance PBRAppearance {
            baseColor 0.333333 1 0.498039
          }
          geometry Sphere {
            radius 0.01
          }
        }
      ]
      name "distance_sensor_r"
      boundingObject USE ddd
      physics Physics {
      }
      lookupTable [
        0 10 0
        10 0 0
      ]
    }
    DistanceSensor {
      translation 0 0.01 -0.05
      rotation 0 1 0 1.57
      children [
        DEF ddd Shape {
          appearance PBRAppearance {
            baseColor 0.333333 1 0.498039
          }
          geometry Sphere {
            radius 0.01
          }
        }
      ]
      name "distance_sensor_l"
      boundingObject USE ddd
      physics Physics {
      }
      lookupTable [
        0 10 0
        10 0 0
      ]
    }
    DistanceSensor {
      translation 0.1 0.01 0
      rotation 1 0 0 1.57
      children [
        DEF ddd Shape {
          appearance PBRAppearance {
            baseColor 0.333333 1 0.498039
          }
          geometry Sphere {
            radius 0.01
          }
        }
      ]
      name "distance_sensor"
      boundingObject USE ddd
      physics Physics {
      }
      lookupTable [
        0 10 0
        10 0 0
      ]
    }
    BallJoint {
      jointParameters BallJointParameters {
        position -544.1204944074011
        anchor 0.07 -0.04 0
      }
      jointParameters2 JointParameters {
        position -634.1220897676549
      }
      jointParameters3 JointParameters {
        position 4088.2305663625816
      }
      endPoint Solid {
        translation 0.07368005956994306 -0.03882858402862172 -9.010606265555388e-06
        rotation -0.9176818756843652 -0.3880773505623088 -0.08518183504107286 -1.1052597905833599
        children [
          DEF ball Shape {
            appearance PBRAppearance {
              baseColor 1 0 0
            }
            geometry Sphere {
              radius 0.03
            }
          }
        ]
        name "solid(2)"
        boundingObject USE ball
        physics Physics {
        }
        linearVelocity 1.5844750787615054e-05 0.07954315031676702 -4.767580361314262e-05
        angularVelocity -2.6517057254951655 0.0005275072213233623 -0.0027710851701009225
      }
    }
    HingeJoint {
      jointParameters HingeJointParameters {
        position 48496.62089667446
        axis 0 0 1
        anchor -0.06 -0.04 -0.05
      }
      device [
        PositionSensor {
          name "l_p_s"
        }
        RotationalMotor {
          name "left_motor"
          acceleration 20
          controlPID 10 4 0
          maxVelocity 100
          minPosition -10
          maxPosition 100000000000
        }
      ]
      endPoint Solid {
        translation -0.060037590443515705 -0.04002441492185592 -0.04999755033990125
        rotation -1.1554786446765944e-09 6.526700128955938e-09 0.9999999999999999 0.22580055445610897
        children [
          DEF wheel Shape {
            appearance PBRAppearance {
              baseColor 1 0 0
            }
            geometry Cylinder {
              height 0.02
              radius 0.03
            }
          }
        ]
        name "solid(1)"
        boundingObject USE wheel
        physics Physics {
        }
        linearVelocity 4.64498824583552e-06 0.07687883290536562 1.0562451955926912e-05
        angularVelocity -2.5625720518136523 0.0001549988920029605 -5.31122135225728e-06
      }
    }
    HingeJoint {
      jointParameters HingeJointParameters {
        position 27289.64461430466
        axis 0 0 1
        anchor -0.06 -0.04 0.05
      }
      device [
        PositionSensor {
          name "r_p_s"
        }
        RotationalMotor {
          name "right_motor"
          acceleration 20
          controlPID 10 4 0
          maxVelocity 100
          minPosition -10
          maxPosition 100000000000
        }
      ]
      endPoint Solid {
        translation -0.06003777950222266 -0.040018047463274746 0.050006331563772224
        rotation 1.0784789322385712e-09 7.316578280789004e-10 1 2.4387100271617483
        children [
          DEF wheel Shape {
            appearance PBRAppearance {
              baseColor 1 0 0
            }
            geometry Cylinder {
              height 0.02
              radius 0.03
            }
          }
        ]
        boundingObject USE wheel
        physics Physics {
        }
        linearVelocity 4.645026105342904e-06 0.07687947503401445 1.0608828779801478e-05
        angularVelocity -2.562572090289533 0.00015499890974107587 -5.311168232449209e-06
      }
    }
    DEF body Shape {
      appearance PBRAppearance {
      }
      geometry Box {
        size 0.2 0.07 0.1
      }
    }
  ]
  name "myrobot"
  boundingObject USE body
  physics DEF body Physics {
  }
  controller "wall-e-controller"
  supervisor TRUE
  linearVelocity 1.3991072196824552e-05 0.07388695273124299 -0.004597984284404667
  angularVelocity 0.07742803641493133 -1.2779095484515666e-05 0.00016174820465352535
}
RectangleArena {
  floorSize 1 3
}
Wall {
  translation -0.55 0 0
  size 0.1 3 0.3
}
DEF ceil Wall {
  translation -0.59999 0 0.32
  rotation 0 1 0 1.5708
  name "wall(1)"
  size 0.05 3 1.2
}
Wall {
  translation 0.56 0 0
  name "wall(2)"
  size 0.1 3 0.3
}
CeilingSpotLight {
  translation -0.3 1 0.2
  name "ceiling light(1)"
  spotLightIntensity 2
  spotLightRadius 0.2
}
CeilingSpotLight {
  translation 0.01 1.34 0.2
  spotLightIntensity 2
  spotLightRadius 0.2
}
CeilingSpotLight {
  translation 0.2 -0.5 0.2
  name "ceiling light(2)"
  spotLightIntensity 2
  spotLightRadius 0.2
}
