#VRML_SIM R2022b utf8

EXTERNPROTO "https://raw.githubusercontent.com/cyberbotics/webots/R2022b/projects/objects/backgrounds/protos/TexturedBackground.proto"
EXTERNPROTO "https://raw.githubusercontent.com/cyberbotics/webots/R2022b/projects/objects/backgrounds/protos/TexturedBackgroundLight.proto"
EXTERNPROTO "https://raw.githubusercontent.com/cyberbotics/webots/R2022b/projects/objects/floors/protos/RectangleArena.proto"
EXTERNPROTO "https://raw.githubusercontent.com/cyberbotics/webots/R2022b/projects/objects/apartment_structure/protos/Wall.proto"
EXTERNPROTO "https://raw.githubusercontent.com/cyberbotics/webots/R2022b/projects/objects/lights/protos/CeilingSpotLight.proto"
EXTERNPROTO "https://raw.githubusercontent.com/cyberbotics/webots/R2022b/projects/devices/robotis/protos/RobotisLds01.proto"

WorldInfo {
}
Viewpoint {
  orientation -0.02726007179110236 0.026722945173251838 0.9992711207110968 1.5915282253709224
  position 0.27892013503171736 -2.6319096357780896 0.48217997617647934
}
TexturedBackground {
}
TexturedBackgroundLight {
  luminosity 0
}
DEF myrobot Robot {
  translation -0.04429922828349786 -0.1904845122635825 0.06911840631472263
  rotation 0.5815684477457312 -0.5729570755456209 -0.5774931429626072 2.094767854518286
  children [
    DistanceSensor {
      translation 0 0.01 0.05
      rotation 0 1 0 -1.57
      children [
        DEF ddd Shape {
          appearance PBRAppearance {
            baseColor 0.333333 1 0.498039
          }
          geometry Sphere {
            radius 0.01
          }
        }
      ]
      name "distance_sensor_r"
      boundingObject USE ddd
      physics Physics {
      }
      lookupTable [
        0 10 0
        10 0 0
      ]
    }
    DistanceSensor {
      translation 0 0.01 -0.05
      rotation 0 1 0 1.57
      children [
        DEF ddd Shape {
          appearance PBRAppearance {
            baseColor 0.333333 1 0.498039
          }
          geometry Sphere {
            radius 0.01
          }
        }
      ]
      name "distance_sensor_l"
      boundingObject USE ddd
      physics Physics {
      }
      lookupTable [
        0 10 0
        10 0 0
      ]
    }
    DistanceSensor {
      translation 0.1 0.01 0
      rotation 1 0 0 1.57
      children [
        DEF ddd Shape {
          appearance PBRAppearance {
            baseColor 0.333333 1 0.498039
          }
          geometry Sphere {
            radius 0.01
          }
        }
      ]
      name "distance_sensor"
      boundingObject USE ddd
      physics Physics {
      }
      lookupTable [
        0 10 0
        10 0 0
      ]
    }
    RobotisLds01 {
      translation 0 0.05 0
      rotation -0.9999998414659299 0.00039816335536657546 0.0003981633553666367 1.5707964853289793
      noise 0.0001
    }
    BallJoint {
      jointParameters BallJointParameters {
        position -504.04828629145
        anchor 0.07 -0.04 0
      }
      jointParameters2 JointParameters {
        position -638.1547254654101
      }
      jointParameters3 JointParameters {
        position 4078.6937940052594
      }
      endPoint Solid {
        translation 0.06986263162899634 -0.03989705936522724 -7.42210378370245e-05
        rotation -0.09269607095527402 0.528342764683291 0.843955781683064 2.871934889861312
        children [
          DEF ball Shape {
            appearance PBRAppearance {
              baseColor 1 0 0
            }
            geometry Sphere {
              radius 0.03
            }
          }
        ]
        name "solid(2)"
        boundingObject USE ball
        physics Physics {
        }
        linearVelocity -3.351387786248571e-07 -1.0660301406566224e-07 1.7414066188109202e-10
        angularVelocity 1.4488592700076314e-05 -1.701434271840501e-05 -1.4881074778525249e-07
      }
    }
    HingeJoint {
      jointParameters HingeJointParameters {
        position 48369.11756071334
        axis 0 0 1
        anchor -0.06 -0.04 -0.05
      }
      device [
        PositionSensor {
          name "l_p_s"
        }
        RotationalMotor {
          name "left_motor"
          acceleration 20
          controlPID 10 4 0
          maxVelocity 100
          minPosition -10
          maxPosition 100000000000
        }
      ]
      endPoint Solid {
        translation -0.060013553686460525 -0.03995727497880317 -0.04999755033990125
        rotation 7.007373174615053e-10 7.60393901645435e-10 -0.9999999999999999 1.6138292630710325
        children [
          DEF wheel Shape {
            appearance PBRAppearance {
              baseColor 1 0 0
            }
            geometry Cylinder {
              height 0.02
              radius 0.03
            }
          }
        ]
        name "solid(1)"
        boundingObject USE wheel
        physics Physics {
        }
        linearVelocity -4.285669990605639e-08 -2.1428506664061863e-07 5.014320310944284e-08
        angularVelocity 7.086994702482636e-07 5.627168677433232e-09 -2.227651222888573e-06
      }
    }
    HingeJoint {
      jointParameters HingeJointParameters {
        position 27162.141278378618
        axis 0 0 1
        anchor -0.06 -0.04 0.05
      }
      device [
        PositionSensor {
          name "r_p_s"
        }
        RotationalMotor {
          name "right_motor"
          acceleration 20
          controlPID 10 4 0
          maxVelocity 100
          minPosition -10
          maxPosition 100000000000
        }
      ]
      endPoint Solid {
        translation -0.06000736472429925 -0.03995878395270236 0.050006331563772224
        rotation 3.931225627439535e-09 -1.319025052312975e-09 1 0.5990802447120239
        children [
          DEF wheel Shape {
            appearance PBRAppearance {
              baseColor 1 0 0
            }
            geometry Cylinder {
              height 0.02
              radius 0.03
            }
          }
        ]
        boundingObject USE wheel
        physics Physics {
        }
        linearVelocity -4.445057778242628e-08 7.607026375559604e-09 4.9941598726986954e-08
        angularVelocity 7.127385748832224e-07 5.656128211325162e-09 -2.2276513510701747e-06
      }
    }
    DEF body Shape {
      appearance PBRAppearance {
      }
      geometry Box {
        size 0.2 0.07 0.1
      }
    }
  ]
  name "myrobot"
  boundingObject USE body
  physics DEF body Physics {
  }
  controller "wall-e-controller"
  supervisor TRUE
  linearVelocity -1.8016401946435314e-07 -1.353546042324371e-07 -4.292329841421956e-08
  angularVelocity 7.091630698096214e-07 5.634071448120064e-09 -2.2276436207113255e-06
}
RectangleArena {
  floorSize 1 3
}
Wall {
  translation -0.55 0 0
  size 0.1 3 1
}
DEF ceil Wall {
  translation -0.59999 0 1.01
  rotation 0 1 0 1.5708
  name "wall(1)"
  size 0.1 3 1.2
}
Wall {
  translation 0.56 0 0
  name "wall(2)"
  size 0.1 3 1
}
CeilingSpotLight {
  translation -0.3 1 0.2
  name "ceiling light(1)"
  spotLightIntensity 2
  spotLightRadius 0.2
}
CeilingSpotLight {
  translation 0.01 1.34 0.2
  spotLightIntensity 2
  spotLightRadius 0.2
}
CeilingSpotLight {
  translation 0.2 -0.5 0.2
  name "ceiling light(2)"
  spotLightIntensity 2
  spotLightRadius 0.2
}
