#VRML_SIM R2022b utf8

EXTERNPROTO "https://raw.githubusercontent.com/cyberbotics/webots/R2022b/projects/objects/backgrounds/protos/TexturedBackground.proto"
EXTERNPROTO "https://raw.githubusercontent.com/cyberbotics/webots/R2022b/projects/objects/backgrounds/protos/TexturedBackgroundLight.proto"
EXTERNPROTO "https://raw.githubusercontent.com/cyberbotics/webots/R2022b/projects/objects/floors/protos/RectangleArena.proto"
EXTERNPROTO "https://raw.githubusercontent.com/cyberbotics/webots/R2022b/projects/objects/apartment_structure/protos/Wall.proto"
EXTERNPROTO "https://raw.githubusercontent.com/cyberbotics/webots/R2022b/projects/objects/lights/protos/CeilingSpotLight.proto"

WorldInfo {
}
Viewpoint {
  orientation -0.10141107910270804 0.1155351718482786 0.988113058865843 1.4526656176385206
  position 0.0007578868142025311 -0.556622555009241 0.06804493754950092
}
TexturedBackground {
}
TexturedBackgroundLight {
  luminosity 0
}
DEF myrobot Robot {
  translation 0.00010060385089599457 -0.0006856068641098536 0.07287162750087789
  rotation -0.5780883938009096 0.5753445320071041 0.5786125460463251 -2.098145077201824
  children [
    DistanceSensor {
      translation 0 0.01 0.05
      rotation 0 1 0 -1.57
      children [
        DEF ddd Shape {
          appearance PBRAppearance {
            baseColor 0.333333 1 0.498039
          }
          geometry Sphere {
            radius 0.01
          }
        }
      ]
      name "distance_sensor_r"
      boundingObject USE ddd
      physics Physics {
      }
      lookupTable [
        0 10 0
        10 0 0
      ]
    }
    DistanceSensor {
      translation 0 0.01 -0.05
      rotation 0 1 0 1.57
      children [
        DEF ddd Shape {
          appearance PBRAppearance {
            baseColor 0.333333 1 0.498039
          }
          geometry Sphere {
            radius 0.01
          }
        }
      ]
      name "distance_sensor_l"
      boundingObject USE ddd
      physics Physics {
      }
      lookupTable [
        0 10 0
        10 0 0
      ]
    }
    DistanceSensor {
      translation 0.1 0.01 0
      rotation 1 0 0 1.57
      children [
        DEF ddd Shape {
          appearance PBRAppearance {
            baseColor 0.333333 1 0.498039
          }
          geometry Sphere {
            radius 0.01
          }
        }
      ]
      name "distance_sensor"
      boundingObject USE ddd
      physics Physics {
      }
      lookupTable [
        0 10 0
        10 0 0
      ]
    }
    BallJoint {
      jointParameters BallJointParameters {
        position -511.69857656899563
        anchor 0.07 -0.04 0
      }
      jointParameters2 JointParameters {
        position -633.9377256599024
      }
      jointParameters3 JointParameters {
        position 4087.832555378677
      }
      endPoint Solid {
        translation 0.06918742048318963 -0.04370514233489965 2.8690995275655102e-05
        rotation -0.47493333561294887 0.36679207762076066 0.7999386842241124 -2.1762026689243505
        children [
          DEF ball Shape {
            appearance PBRAppearance {
              baseColor 1 0 0
            }
            geometry Sphere {
              radius 0.03
            }
          }
        ]
        name "solid(2)"
        boundingObject USE ball
        physics Physics {
        }
        linearVelocity -3.041941617600292e-07 -1.3074562754698851e-07 -4.770027168147607e-07
        angularVelocity 1.272915906918e-05 -1.5513569788486977e-05 -9.876482442777335e-08
      }
    }
    HingeJoint {
      jointParameters HingeJointParameters {
        position 48369.11756071834
        axis 0 0 1
        anchor -0.06 -0.04 -0.05
      }
      device [
        PositionSensor {
          name "l_p_s"
        }
        RotationalMotor {
          name "left_motor"
          acceleration 20
          controlPID 10 4 0
          maxVelocity 100
          minPosition -10
          maxPosition 100000000000
        }
      ]
      endPoint Solid {
        translation -0.06001355368667406 -0.03995727497887094 -0.04999755033990125
        rotation 7.007373172386208e-10 7.60393905217162e-10 -1 1.6138292580724427
        children [
          DEF wheel Shape {
            appearance PBRAppearance {
              baseColor 1 0 0
            }
            geometry Cylinder {
              height 0.02
              radius 0.03
            }
          }
        ]
        name "solid(1)"
        boundingObject USE wheel
        physics Physics {
        }
        linearVelocity -4.408240388751869e-08 -2.3581734646970625e-07 -1.5949931235564622e-07
        angularVelocity 2.412463160803e-06 -1.2357032671552902e-07 -2.0153860454010937e-06
      }
    }
    HingeJoint {
      jointParameters HingeJointParameters {
        position 27162.141278373703
        axis 0 0 1
        anchor -0.06 -0.04 0.05
      }
      device [
        PositionSensor {
          name "r_p_s"
        }
        RotationalMotor {
          name "right_motor"
          acceleration 20
          controlPID 10 4 0
          maxVelocity 100
          minPosition -10
          maxPosition 100000000000
        }
      ]
      endPoint Solid {
        translation -0.06000736472409667 -0.039958783952666166 0.050006331563772224
        rotation 3.931225655479818e-09 -1.3190250724695933e-09 1 0.5990802397970947
        children [
          DEF wheel Shape {
            appearance PBRAppearance {
              baseColor 1 0 0
            }
            geometry Cylinder {
              height 0.02
              radius 0.03
            }
          }
        ]
        boundingObject USE wheel
        physics Physics {
        }
        linearVelocity -4.3918103500573575e-08 -3.4480440757290637e-08 -1.7140029873216017e-07
        angularVelocity 2.408357519902392e-06 -1.235666853160738e-07 -2.0153859149558823e-06
      }
    }
    DEF body Shape {
      appearance PBRAppearance {
      }
      geometry Box {
        size 0.2 0.07 0.1
      }
    }
  ]
  name "myrobot"
  boundingObject USE body
  physics DEF body Physics {
  }
  controller "wall-e-controller"
  supervisor TRUE
}
RectangleArena {
  floorSize 1 3
}
Wall {
  translation -0.55 0 0
  size 0.1 3 0.3
}
DEF ceil Wall {
  translation -0.59999 0 0.32
  rotation 0 1 0 1.5708
  name "wall(1)"
  size 0.05 3 1.2
}
Wall {
  translation 0.56 0 0
  name "wall(2)"
  size 0.1 3 0.3
}
CeilingSpotLight {
  translation -0.3 1 0.2
  name "ceiling light(1)"
  spotLightIntensity 2
  spotLightRadius 0.2
}
CeilingSpotLight {
  translation 0.01 1.34 0.2
  spotLightIntensity 2
  spotLightRadius 0.2
}
CeilingSpotLight {
  translation 0.2 -0.5 0.2
  name "ceiling light(2)"
  spotLightIntensity 2
  spotLightRadius 0.2
}
